#VRML_SIM R2019a utf8
WorldInfo {
}
Viewpoint {
  orientation 0.5449666044914627 -0.6672805409708686 -0.5076889595319861 4.384725432697691
  position 0.5973193036003304 2.414297256300008 0.2032487720201478
}
TexturedBackground {
}
TexturedBackgroundLight {
}
Floor {
}
Robot {
  translation 0 0.1 0
  children [
    DEF BODY Shape {
      appearance PBRAppearance {
        baseColor 0.6924238956282902 0.16743724727244982 0.9133287556267643
        roughness 1
      }
      geometry Cylinder {
        height 0.08
        radius 0.14
      }
    }
    DEF WH_1 Transform {
      translation 0 0 0.14
      children [
        DEF WHEEL1 HingeJoint {
          jointParameters HingeJointParameters {
            axis 0 0 1
            anchor 0 0 0.02
          }
          endPoint Solid {
            translation 0 0 -0.01
            rotation 0 0 1 0
            children [
              DEF sr1 HingeJoint {
                jointParameters HingeJointParameters {
                  anchor 0 0.06 0.02
                }
                endPoint Solid {
                  translation 0 0.06 0.02
                  rotation 1 0 0 0
                  children [
                    DEF r1 Transform {
                      rotation 0 0 1 1.5708
                      children [
                        DEF SMALL_WHEEL_SHAPE Shape {
                          appearance PBRAppearance {
                            baseColor 1 0.752941 0.796078
                            roughness 1
                            metalness 0
                          }
                          geometry Cylinder {
                            height 0.03
                            radius 0.012
                          }
                        }
                      ]
                    }
                  ]
                  name "sr1"
                  boundingObject USE r1
                  physics Physics {
                    density -1
                    mass 0.1
                  }
                }
              }
              DEF sr2 HingeJoint {
                jointParameters HingeJointParameters {
                  axis 0.707107 0.707107 0
                  anchor -0.04535 0.04535 0.02
                }
                endPoint Solid {
                  translation -0.04535 0.04535 0.02
                  rotation 0.7071067811865476 0.7071067811865476 0 0
                  children [
                    DEF r2 Transform {
                      rotation 0 0 1 2.27
                      children [
                        USE SMALL_WHEEL_SHAPE
                      ]
                    }
                  ]
                  name "sr2"
                  boundingObject USE r2
                  physics Physics {
                    density -1
                    mass 0.1
                  }
                }
              }
              DEF sr3 HingeJoint {
                jointParameters HingeJointParameters {
                  anchor 0 -0.06 0.02
                }
                endPoint Solid {
                  translation 0 -0.06 0.02
                  rotation 1 0 0 0
                  children [
                    DEF r3 Transform {
                      rotation 0 0 1 1.5708
                      children [
                        USE SMALL_WHEEL_SHAPE
                      ]
                    }
                  ]
                  name "sr3"
                  boundingObject USE r3
                  physics Physics {
                    density -1
                    mass 0.1
                  }
                }
              }
              DEF sr4 HingeJoint {
                jointParameters HingeJointParameters {
                  axis 0.707107 0.707107 0
                  anchor 0.04535 -0.04535 0.02
                }
                endPoint Solid {
                  translation 0.04535 -0.04535 0.02
                  rotation 0.7071067811865476 0.7071067811865476 0 0
                  children [
                    DEF r4 Transform {
                      rotation 0 0 1 2.27
                      children [
                        USE SMALL_WHEEL_SHAPE
                      ]
                    }
                  ]
                  name "sr4"
                  boundingObject USE r4
                  physics Physics {
                    density -1
                    mass 0.1
                  }
                }
              }
              DEF sr5 HingeJoint {
                jointParameters HingeJointParameters {
                  axis 0 1 0
                  anchor -0.06 0 0.02
                }
                endPoint Solid {
                  translation -0.06 0 0.02
                  children [
                    DEF r5 Transform {
                      children [
                        USE SMALL_WHEEL_SHAPE
                      ]
                    }
                  ]
                  name "sr5"
                  boundingObject USE r5
                  physics Physics {
                    density -1
                    mass 0.1
                  }
                }
              }
              DEF sr6 HingeJoint {
                jointParameters HingeJointParameters {
                  axis 0 1 0
                  anchor 0.06 0 0.02
                }
                endPoint Solid {
                  translation 0.06 0 0.02
                  children [
                    DEF r6 Transform {
                      children [
                        USE SMALL_WHEEL_SHAPE
                      ]
                    }
                  ]
                  name "sr6"
                  boundingObject USE r6
                  physics Physics {
                    density -1
                    mass 0.1
                  }
                }
              }
              DEF sr7 HingeJoint {
                jointParameters HingeJointParameters {
                  axis -0.707107 0.707107 0
                  anchor -0.04535 -0.04535 0.02
                }
                endPoint Solid {
                  translation -0.04535 -0.04535 0.02
                  rotation -0.7071067811865476 0.7071067811865476 0 0
                  children [
                    DEF r7 Transform {
                      rotation 0 0 1 0.76
                      children [
                        USE SMALL_WHEEL_SHAPE
                      ]
                    }
                  ]
                  name "sr7"
                  boundingObject USE r7
                  physics Physics {
                    density -1
                    mass 0.1
                  }
                }
              }
              DEF sr8 HingeJoint {
                jointParameters HingeJointParameters {
                  axis -0.707107 0.707107 0
                  anchor 0.04535 0.04535 0.02
                }
                endPoint Solid {
                  translation 0.04535 0.04535 0.02
                  rotation -0.7071067811865476 0.7071067811865476 0 0
                  children [
                    DEF r8 Transform {
                      rotation 0 0 1 0.76
                      children [
                        USE SMALL_WHEEL_SHAPE
                      ]
                    }
                  ]
                  name "sr8"
                  boundingObject USE r8
                  physics Physics {
                    density -1
                    mass 0.1
                  }
                }
              }
              DEF WHEEL_TRANS Transform {
                translation 0 0 0.02
                rotation 1 0 0 1.5708
                children [
                  DEF WHEEL_SHAPE Shape {
                    appearance PBRAppearance {
                      baseColor 0.9333333333333333 0.33600366216525523 0.33600366216525523
                      roughness 1
                    }
                    geometry Cylinder {
                      height 0.02
                      radius 0.06
                      subdivision 20
                    }
                  }
                ]
              }
            ]
            boundingObject USE WHEEL_TRANS
            physics Physics {
            }
          }
        }
      ]
    }
    DEF WH_2 Transform {
      translation 0.13 0 -0.069
      rotation 0 1 0 2.094395096
      children [
        DEF WHEEL1 HingeJoint {
          jointParameters HingeJointParameters {
            axis 0 0 1
            anchor 0 0 0.02
          }
          endPoint Solid {
            translation 0 0 -0.01
            rotation 0 0 1 0
            children [
              DEF sr1 HingeJoint {
                jointParameters HingeJointParameters {
                  anchor 0 0.06 0.02
                }
                endPoint Solid {
                  translation 0 0.06 0.02
                  rotation 1 0 0 0
                  children [
                    DEF r1 Transform {
                      rotation 0 0 1 1.5708
                      children [
                        DEF SMALL_WHEEL_SHAPE Shape {
                          appearance PBRAppearance {
                            baseColor 1 0.752941 0.796078
                            roughness 1
                            metalness 0
                          }
                          geometry Cylinder {
                            height 0.03
                            radius 0.012
                          }
                        }
                      ]
                    }
                  ]
                  name "sr1"
                  boundingObject USE r1
                  physics Physics {
                    density -1
                    mass 0.1
                  }
                }
              }
              DEF sr2 HingeJoint {
                jointParameters HingeJointParameters {
                  axis 0.707107 0.707107 0
                  anchor -0.04535 0.04535 0.02
                }
                endPoint Solid {
                  translation -0.04535 0.04535 0.02
                  rotation 0.7071067811865476 0.7071067811865476 0 0
                  children [
                    DEF r2 Transform {
                      rotation 0 0 1 2.27
                      children [
                        USE SMALL_WHEEL_SHAPE
                      ]
                    }
                  ]
                  name "sr2"
                  boundingObject USE r2
                  physics Physics {
                    density -1
                    mass 0.1
                  }
                }
              }
              DEF sr3 HingeJoint {
                jointParameters HingeJointParameters {
                  anchor 0 -0.06 0.02
                }
                endPoint Solid {
                  translation 0 -0.06 0.02
                  rotation 1 0 0 0
                  children [
                    DEF r3 Transform {
                      rotation 0 0 1 1.5708
                      children [
                        USE SMALL_WHEEL_SHAPE
                      ]
                    }
                  ]
                  name "sr3"
                  boundingObject USE r3
                  physics Physics {
                    density -1
                    mass 0.1
                  }
                }
              }
              DEF sr4 HingeJoint {
                jointParameters HingeJointParameters {
                  axis 0.707107 0.707107 0
                  anchor 0.04535 -0.04535 0.02
                }
                endPoint Solid {
                  translation 0.04535 -0.04535 0.02
                  rotation 0.7071067811865476 0.7071067811865476 0 0
                  children [
                    DEF r4 Transform {
                      rotation 0 0 1 2.27
                      children [
                        USE SMALL_WHEEL_SHAPE
                      ]
                    }
                  ]
                  name "sr4"
                  boundingObject USE r4
                  physics Physics {
                    density -1
                    mass 0.1
                  }
                }
              }
              DEF sr5 HingeJoint {
                jointParameters HingeJointParameters {
                  axis 0 1 0
                  anchor -0.06 0 0.02
                }
                endPoint Solid {
                  translation -0.06 0 0.02
                  children [
                    DEF r5 Transform {
                      children [
                        USE SMALL_WHEEL_SHAPE
                      ]
                    }
                  ]
                  name "sr5"
                  boundingObject USE r5
                  physics Physics {
                    density -1
                    mass 0.1
                  }
                }
              }
              DEF sr6 HingeJoint {
                jointParameters HingeJointParameters {
                  axis 0 1 0
                  anchor 0.06 0 0.02
                }
                endPoint Solid {
                  translation 0.06 0 0.02
                  children [
                    DEF r6 Transform {
                      children [
                        USE SMALL_WHEEL_SHAPE
                      ]
                    }
                  ]
                  name "sr6"
                  boundingObject USE r6
                  physics Physics {
                    density -1
                    mass 0.1
                  }
                }
              }
              DEF sr7 HingeJoint {
                jointParameters HingeJointParameters {
                  axis -0.707107 0.707107 0
                  anchor -0.04535 -0.04535 0.02
                }
                endPoint Solid {
                  translation -0.04535 -0.04535 0.02
                  rotation -0.7071067811865476 0.7071067811865476 0 0
                  children [
                    DEF r7 Transform {
                      rotation 0 0 1 0.76
                      children [
                        USE SMALL_WHEEL_SHAPE
                      ]
                    }
                  ]
                  name "sr7"
                  boundingObject USE r7
                  physics Physics {
                    density -1
                    mass 0.1
                  }
                }
              }
              DEF sr8 HingeJoint {
                jointParameters HingeJointParameters {
                  axis -0.707107 0.707107 0
                  anchor 0.04535 0.04535 0.02
                }
                endPoint Solid {
                  translation 0.04535 0.04535 0.02
                  rotation -0.7071067811865476 0.7071067811865476 0 0
                  children [
                    DEF r8 Transform {
                      rotation 0 0 1 0.76
                      children [
                        USE SMALL_WHEEL_SHAPE
                      ]
                    }
                  ]
                  name "sr8"
                  boundingObject USE r8
                  physics Physics {
                    density -1
                    mass 0.1
                  }
                }
              }
              DEF WHEEL_TRANS Transform {
                translation 0 0 0.02
                rotation 1 0 0 1.5708
                children [
                  DEF WHEEL_SHAPE Shape {
                    appearance PBRAppearance {
                      baseColor 0.9333333333333333 0.33600366216525523 0.33600366216525523
                      roughness 1
                    }
                    geometry Cylinder {
                      height 0.02
                      radius 0.06
                      subdivision 20
                    }
                  }
                ]
              }
            ]
            name "solid(1)"
            boundingObject USE WHEEL_TRANS
            physics Physics {
            }
          }
        }
      ]
    }
    DEF WH_3 Transform {
      translation -0.13 0 -0.069
      rotation 0 0.9999999999999999 0 -2.0944
      children [
        DEF WHEEL1 HingeJoint {
          jointParameters HingeJointParameters {
            axis 0 0 1
            anchor 0 0 0.02
          }
          endPoint Solid {
            translation 0 0 -0.01
            rotation 0 0 1 0
            children [
              DEF sr1 HingeJoint {
                jointParameters HingeJointParameters {
                  anchor 0 0.06 0.02
                }
                endPoint Solid {
                  translation 0 0.06 0.02
                  rotation 1 0 0 0
                  children [
                    DEF r1 Transform {
                      rotation 0 0 1 1.5708
                      children [
                        DEF SMALL_WHEEL_SHAPE Shape {
                          appearance PBRAppearance {
                            baseColor 1 0.752941 0.796078
                            roughness 1
                            metalness 0
                          }
                          geometry Cylinder {
                            height 0.03
                            radius 0.012
                          }
                        }
                      ]
                    }
                  ]
                  name "sr1"
                  boundingObject USE r1
                  physics Physics {
                    density -1
                    mass 0.1
                  }
                }
              }
              DEF sr2 HingeJoint {
                jointParameters HingeJointParameters {
                  axis 0.707107 0.707107 0
                  anchor -0.04535 0.04535 0.02
                }
                endPoint Solid {
                  translation -0.04535 0.04535 0.02
                  rotation 0.7071067811865476 0.7071067811865476 0 0
                  children [
                    DEF r2 Transform {
                      rotation 0 0 1 2.27
                      children [
                        USE SMALL_WHEEL_SHAPE
                      ]
                    }
                  ]
                  name "sr2"
                  boundingObject USE r2
                  physics Physics {
                    density -1
                    mass 0.1
                  }
                }
              }
              DEF sr3 HingeJoint {
                jointParameters HingeJointParameters {
                  anchor 0 -0.06 0.02
                }
                endPoint Solid {
                  translation 0 -0.06 0.02
                  rotation 1 0 0 0
                  children [
                    DEF r3 Transform {
                      rotation 0 0 1 1.5708
                      children [
                        USE SMALL_WHEEL_SHAPE
                      ]
                    }
                  ]
                  name "sr3"
                  boundingObject USE r3
                  physics Physics {
                    density -1
                    mass 0.1
                  }
                }
              }
              DEF sr4 HingeJoint {
                jointParameters HingeJointParameters {
                  axis 0.707107 0.707107 0
                  anchor 0.04535 -0.04535 0.02
                }
                endPoint Solid {
                  translation 0.04535 -0.04535 0.02
                  rotation 0.7071067811865476 0.7071067811865476 0 0
                  children [
                    DEF r4 Transform {
                      rotation 0 0 1 2.27
                      children [
                        USE SMALL_WHEEL_SHAPE
                      ]
                    }
                  ]
                  name "sr4"
                  boundingObject USE r4
                  physics Physics {
                    density -1
                    mass 0.1
                  }
                }
              }
              DEF sr5 HingeJoint {
                jointParameters HingeJointParameters {
                  axis 0 1 0
                  anchor -0.06 0 0.02
                }
                endPoint Solid {
                  translation -0.06 0 0.02
                  children [
                    DEF r5 Transform {
                      children [
                        USE SMALL_WHEEL_SHAPE
                      ]
                    }
                  ]
                  name "sr5"
                  boundingObject USE r5
                  physics Physics {
                    density -1
                    mass 0.1
                  }
                }
              }
              DEF sr6 HingeJoint {
                jointParameters HingeJointParameters {
                  axis 0 1 0
                  anchor 0.06 0 0.02
                }
                endPoint Solid {
                  translation 0.06 0 0.02
                  children [
                    DEF r6 Transform {
                      children [
                        USE SMALL_WHEEL_SHAPE
                      ]
                    }
                  ]
                  name "sr6"
                  boundingObject USE r6
                  physics Physics {
                    density -1
                    mass 0.1
                  }
                }
              }
              DEF sr7 HingeJoint {
                jointParameters HingeJointParameters {
                  axis -0.707107 0.707107 0
                  anchor -0.04535 -0.04535 0.02
                }
                endPoint Solid {
                  translation -0.04535 -0.04535 0.02
                  rotation -0.7071067811865476 0.7071067811865476 0 0
                  children [
                    DEF r7 Transform {
                      rotation 0 0 1 0.76
                      children [
                        USE SMALL_WHEEL_SHAPE
                      ]
                    }
                  ]
                  name "sr7"
                  boundingObject USE r7
                  physics Physics {
                    density -1
                    mass 0.1
                  }
                }
              }
              DEF sr8 HingeJoint {
                jointParameters HingeJointParameters {
                  axis -0.707107 0.707107 0
                  anchor 0.04535 0.04535 0.02
                }
                endPoint Solid {
                  translation 0.04535 0.04535 0.02
                  rotation -0.7071067811865476 0.7071067811865476 0 0
                  children [
                    DEF r8 Transform {
                      rotation 0 0 1 0.76
                      children [
                        USE SMALL_WHEEL_SHAPE
                      ]
                    }
                  ]
                  name "sr8"
                  boundingObject USE r8
                  physics Physics {
                    density -1
                    mass 0.1
                  }
                }
              }
              DEF WHEEL_TRANS Transform {
                translation 0 0 0.02
                rotation 1 0 0 1.5708
                children [
                  DEF WHEEL_SHAPE Shape {
                    appearance PBRAppearance {
                      baseColor 0.9333333333333333 0.33600366216525523 0.33600366216525523
                      roughness 1
                    }
                    geometry Cylinder {
                      height 0.02
                      radius 0.06
                      subdivision 20
                    }
                  }
                ]
              }
            ]
            name "solid(2)"
            boundingObject USE WHEEL_TRANS
            physics Physics {
            }
          }
        }
      ]
    }
  ]
  boundingObject USE BODY
  physics Physics {
  }
}
